Workbook
Name answer: #REF!
Name answer: #REF!
Name IndustryCode: #REF!
Name IndustryCode: #REF!
Name no_yes: '[1]Billing & Order Details'!$B$108:$B$109
Name sic: '[2]Picklist'!$A$2:$A$92
Name sic: #REF!
Name sic: #REF!
Name yes_no: '[2]Billing & Order Details'!$B$108:$B$109
Name yes_no: #REF!

Sheet General Info INT
C1: =IF(#REF!="NextGen","NextGen eOrder","Director eOrder") -> #REF!
C4: OUTRIGHT ORDER FORM
A6: General Info (Internal)
A15: Sales Information
A17: Sales Person* | C17: Purchase Order
A19: Email Address* | C19: Order Date
A21: Contact Number
A26: Customer Information | D26: Opportunity entered in Saleforce
A27: Company Name* | C27: Opportunity Field ID*
A29: Trading As Name* | C29: Industry*
C30: How did they hear about Teletrac Navman?
A31: Existing TN Customer? | B31: --Select--
A33: Customer ID | B33: =IF(B31="Yes","Enter SAP Customer ID here (if known)","") | C33: ABN Number*
A35: Address* | C35: State*
A37: Suburb* | C37: Postcode*
A39: General Contact | C39: Accounts Contact
A40: Name* | C40: Name*
A42: Email Address* | C42: Email Address*
A44: Phone Number* | C44: Phone Number*
A46: Onboarding Contact | B46: (If new Transport Customer, please advise who will be owning the training component)
A47: Name* | C47: Phone Number*
A49: Email Address*
A52: Order & Billing Information | C52: =IF(B53="--Select--","Select an Order Reason",IF(B53="New Customer","Submit eOrder form with a new Rental Agreement, Proof of ID & Direct Debit information",IF(B53="Add to Fleet","Submit eOrder form with a new Add to Fleet Form",IF(B53="Renewal","Submit eOrder with a new Rental Agreement & list the units to be Renewed, in the Fleet Information tab (enter AVL/Director vehicle names &/or serial numbers)",IF(B53="Replacement","List the units to be Replaced in the Fleet Information tab (enter AVL/Director vehicle names &/or unit serial numbers)",""))))) -> Select an Order Reason
A53: Order Reason | B53: --Select--
A55: Hardware/Install Billing | B55: --Select-- | C55: Customer PO
A57: If billing to other, specify SAP ID | C57: Monthly Service Fee (per unit) | D57: 0
A60: © 2019 Teletrac Navman
B61: Order Reason | C61: Hardware Billing | D61: Service Fee Billing
A62: --Select-- | B62: --Select-- | C62: --Select-- | D62: --Select--
A63: Yes | B63: New Customer | C63: Bill to Customer | D63: Teletrac Navman Billed
A64: No | B64: Add to Fleet | C64: Bill to Other | D64: Telstra Billed
B65: Renewal | D65: Dealer Demo
B66: Replacement
B67: Accessories/Parts Only
B68: Upsell

Sheet General Information
C1: Platform | D1: TN360
C2: Director Sync Enabled | D2: TRUE
A4: General Info
A6: Dealer Information
A7: Dealership Name* | B7: Navtek Tracking | C7: Purchase Order
A9: Physical Address* | B9: PO Box 84 , Balgowlah , 2093 , New South Wales | C9: Order Date | D9: May 13, 2026
A11: Email Address* | B11: sophia@navtek.com.au | C11: Sales Representative* | D11: Sophia Carvalho
A13: Contact Number | B13: . | C13: TN Regional Manager* | D13: Jason O'Reilly
A17: Customer Information
A18: Company Name* | B18: Cosmo Cranes Pty Ltd | C18: Opportunity Field ID* | D18: 006VP00000YLgyL
A20: Trading As Name* | C20: Industry* | D20: 1005 Machinery and Equipm
C21: Industry Sub Code*
A22: Customer ID | B22: 120561 | D22: 0209 Lift/Crane
A24: Address* | B24: 28 Riverside Road | C24: ABN Number* | D24: 72107040746
A26: Suburb* | B26: Chipping Norton | C26: State* | D26: New South Wales
C28: Postcode* | D28: 2170
A30: Change of Ownership
A31: New Business Account from a COR | B31: FALSE | C31: Customer to Customer COR | D31: FALSE
A33: General Contact | C33: Accounts Contact
A34: Name* | B34: Natalie Beattie | C34: Name* | D34: Natalie Beattie
A36: Email Address* | B36: reception@cosmocranes.com.au | C36: Email Address* | D36: reception@cosmocranes.com.au
A38: Phone Number* | B38: 1300 1 COSMO | C38: Phone Number* | D38: 1300 1 COSMO
A40: IT Contact for BYOD
B41: --Select-- | C41: Phone Number*
A43: Name* | C43: Email Address*
A46: Order & Billing Information | C46: Is this order intended for vehicles with existing harware installed *
A47: Order Reason * | B47: Hardware Only (Replacement unit) | D47: No
A49: Hardware Billing | B49: Bill to Dealer | C49: Customer PO
A51: Service Fee Billing | B51: Teletrac Navman Billed | C51: Migration required 3g to 4G | D51: No
A53: SIM Activation By | B53: Teletrac Navman | C53: Additional Sims required for existing iFace Qty needed
A56: ©2022 Teletrac Navman

Sheet Renewal - Recontract
E1: =IF(#REF!="NextGen","NextGen eOrder","Director eOrder") -> #REF!
E4: OUTRIGHT ORDER FORM
A6: Renewal - Recontract
B9: Customer Name and Account Number
A11: Contract to be cancelled | B11: Sales Order to be cancelled | C11: Vehicles | D11: Stop all billing on Sales Order | E11: If No, Sales order should be decremented by these Qty
E12: Material Code | G12: Service Description | I12: QTY (- #)
D13: YES
D22: YES
D31: YES
D40: YES
D49: YES
A59: © 2019 Teletrac Navman

Sheet Billing, Order & SIM INT
A1: --Select-- | C1: --Select--
A2: Yes | C2: ConEx 10-Way I/O cable
A3: No | C3: ConEx 8-Way cable
D5: =IF(#REF!="NextGen","NextGen eOrder","Director eOrder") -> #REF!
D8: OUTRIGHT ORDER FORM
A10: Billing, Order & SIM Activation Details (Internal)
A21: ConEx & Third-party Device Integration | E21: If 'Yes', select ConEx Cable
A22: Is additional monitoring required for a vehicle's/equipment's auxiliary function? Example: Duress Button, Door Open/Close, etc. | D22: --Select-- | E22: --Select--
A23: Select the ConEx connection required: | D23: What is being monitored or installed?
A24: --Select-- | B24: Digger (ON / OFF) | D24: Example: Temperature, Duress Button, etc.
A25: --Select-- | B25: Battery Isolation (ON / OFF)
A26: --Select-- | B26: Engine (STARTED / STOPPED)
A27: --Select-- | B27: Working (WORKING / NOT WORKING)
A28: --Select-- | B28: Site (ENTERING / LEAVING)
A29: --Select-- | B29: Dump (ON / OFF)
A32: Billing Info
A34: Hardware/Install Billing | B34: ='General Info INT'!B55 -> --Select-- | C34: Monthly Service Fee | D34: ='General Info INT'!D57 -> 0 | E34: per unit
A36: If billing to other, specify SAP ID | B36: ='General Info INT'!B57 -> 0 | C36: SIM Activation By | D36: Teletrac Navman SIM
A39: Hardware | D39: Dealer Buy Price Per Unit
A40: Qty | B40: Product Type | C40: Part Number | E40: Subtotal
B41: Compliance Essential iFace + Compliance | C41: 10001937 | D41: 665 | E41: =A41*D41 -> 0
B42: Compliance Professional iFace + Compliance + Qube + NextGen | C42: 10001937 + 10001352 | D42: 1390 | E42: =A42*D42 -> 0
B43: #1 IAP Essential - Tracking, with iFace iFace + Qube + IVU + NextGen | C43: 10001937 + 10001828 + 10001352 | D43: 2215 | E43: =A43*D43 -> 0
B44: #2 IAP Professional - Tracking, Compliance iFace + Compliance + Qube + IVU + NextGen | C44: 10001937 + 10001828 + 10001352 | D44: 2215 | E44: =A44*D44 -> 0
B45: #3 IAP Essential - Tracking, no iFace Qube + IVU + NextGen | C45: 10001828 + 10001352 | D45: 1611 | E45: =A45*D45 -> 0
B46: #4 IAP Essential - no Tracking, with iFace iFace + IVU + NextGen | C46: 10001937 + 10001828 | D46: 1835 | E46: =A46*D46 -> 0
B47: #5 IAP Professional - no Tracking, with Compliance iFace + Compliance + IVU + NextGen | C47: 10001937 + 10001828 | D47: 1835 | E47: =A47*D47 -> 0
B48: #6 IAP Only - no Tracking, no iFace IVU + IAP + NextGen | C48: 10001828 | D48: 1231 | E48: =A48*D48 -> 0
B49: Next G Qube | C49: 10001352 | D49: 980 | E49: =A49*D49 -> 0
B50: Next G Qube 50 | C50: 10001370 | D50: 495 | E50: =A50*D50 -> 0
B51: Next G Qtanium 100 | C51: 10001340 | D51: 530 | E51: =A51*D51 -> 0
B52: Next G Qtanium 200 | C52: 10001371 | D52: 595 | E52: =A52*D52 -> 0
B53: Next G Qtanium 400 | C53: 10001608 | D53: 980 | E53: =A53*D53 -> 0
B54: M-Nav 950 | C54: 10001891 | D54: 699 | E54: =A54*D54 -> 0
B55: MDT | C55: 10001270 | D55: 346.5 | E55: =A55*D55 -> 0
B56: Satellite Communication Device | C56: 10001183 | D56: 1160 | E56: =A56*D56 -> 0
B57: Data Capture Unit (DCU) for EMS | C57: 10001276 | D57: 395 | E57: =A57*D57 -> 0
B58: Temperature Monitoring Kit | C58: 10001450 + 10001300 + 10001288 + 10001289 + 10001294 | D58: 372 | E58: =A58*D58 -> 0
B59: NavCAN1 | C59: 10001433 | D59: 475 | E59: =A59*D59 -> 0
B60: NavCAN2 | C60: 10001434 | D60: 575 | E60: =A60*D60 -> 0
...

Sheet MIGRATE TO TN360
I1: Migration to TN360
B5: Is Migration required? | I5: No
B7: CSS Representive Engaged | I7: Padma Aluri
B9: Approved Scenarios
B11: Any integration required to be transferred (Please name eg FTC)
B13: Any peripheral devices required to be transferred (Please name )

Sheet Billing, Order & SIM Activation
A1: --Select-- | C1: --Select--
A2: Yes | C2: ConEx 10-Way I/O cable
A3: No | C3: ConEx 8-Way cable
F5: ALL PLATFORMS
A10: Billing, Order & SIM Activation Details
E12: Additional Notes for Finance:
E13: N/A
A21: ConEx & Third-party Device Integration
A22: Is additional monitoring required for a vehicle's/equipment's auxiliary function? Example: Duress Button, Door Open/Close, etc.
A23: Select the ConEx connection required:
A24: --Select-- | B24: Digger (ON / OFF)
A25: --Select-- | B25: Battery Isolation (ON / OFF)
A26: --Select-- | B26: Engine (STARTED / STOPPED)
A27: --Select-- | B27: Working (WORKING / NOT WORKING)
A28: --Select-- | B28: Site (ENTERING / LEAVING)
A29: --Select-- | B29: Dump (ON / OFF)
A32: Billing & SIM Activation
A34: Hardware Billing | B34: ='General Information'!B49 -> Bill to Dealer | C34: Total Monthly Payment | D34: 0
A36: Service Fee Billing | B36: Teletrac Navman Billed | C36: Total Dealer Commission | D36: 0
A38: SIM Activation By | B38: Teletrac Navman | C38: Total Contract Value | D38: 21.28
A40: GPIO | B40: No | C40: Is Teletrac Navman Arranging Install? | D40: No
C42: Total Install Value | D42: 0
A45: Quantity | B45: Product Name | C45: Product Description | D45: Product Code | E45: Product Family | F45: Term | G45: Sales Price per Unit
A46: 1 | B46: Commissions & Fees | C46: Commissions & Fees | D46: 85000001 | E46: Internal Use Only | F46: 12 | G46: 0
A47: 1 | B47: Driver ID - DID3 Dallas reader | C47: Driver ID 3 Green Keyfob Reader | D47: 10003496 | E47: Parts | F47: 1 | G47: 21.28
G71: © 2022 Teletrac Navman

Sheet GPIO
A1: ALL PLATFORMS
A6: GPIO Details
A9: GPIO Configuration | B9: GPIO is set at the company level and will apply to all vehicles. Any special configuration is to be setup during installation.
B10: Select one event per input only and mark with an X
A13: GPIO Configuration DI1
A14: GPIO Configuration DI2
A15: GPIO Configuration DI3

Sheet OBM Scale Provider
A1: ALL PLATFORMS
A6: OBM Scale Provider
A8: OBM Scale Provider | B8: If the Opportunity has OBM Products on it, the eOrder workflow will required Scales.
A9: OBM Board Scales:

Sheet Delivery & Install Details
A1: ALL PLATFORMS
A6: Delivery Details | K6: TN to Arrange Install Details
J8: Additional Notes for Provisioning and Service | K8: ACT City(s)
A9: Customer Details | J9: To be used for: 015678004069783 - going into CF57TP
A10: Company | B10: Cosmo Cranes Pty Ltd | D10: Is Teletrac Navman Organising Install? | G10: No | K10: ACT # of Installs
A11: Address | B11: 28 Riverside Road | K11: NT City(s)
A12: Suburb | B12: Chipping Norton | H12: =IF($G$10="--Select--","Mandatory field",IF($G$10="No","Note: installations can only be performed by certified installers","Teletrac Navman Installation Costs will be applied")) -> Note: installations can only be performed by certified installers
A13: State | B13: New South Wales | D13: Which address is the Delivery going to? | G13: Customer Address | K13: NT # of Installs
A14: Postcode | B14: 2170 | K14: NSW City(s)
A15: Contact | B15: Natalie Beattie | D15: =IF(G10="NO","Delivery Address","") -> Delivery Address
A16: Phone No | B16: 1300 1 COSMO | D16: Delivery Address | K16: NSW # of Installs
A17: Email | B17: reception@cosmocranes.com.au | D17: Company Name | E17: Cosmo Cranes Pty Ltd | K17: QLD City(s)
A18: Order Reason | B18: Hardware Only (Replacement unit) | D18: Address | E18: 28 Riverside Road,Chipping Norton,2170,New South Wales
A19: SAP ID | B19: 120561 | D19: Contact Name | K19: QLD # of Installs
D20: Contact Email | K20: SA City(s)
A21: Dealer Details
A22: Dealership | B22: ='General Information'!B7 -> Navtek Tracking | K22: SA # of Installs
A23: Address | B23: ='General Information'!B9 -> PO Box 84 , Balgowlah , 2093 , New South Wales | K23: TAS City(s)
A24: Email | B24: ='General Information'!B11 -> sophia@navtek.com.au
A25: Sales Representative | B25: ='General Information'!D11 -> Sophia Carvalho | K25: TAS # of Installs
A26: Contact No. | B26: ='General Information'!B13 -> . | K26: VIC City(s)
K28: VIC # of Installs
K29: WA City(s)
K31: WA # of Installs
A32: © 2022 Teletrac Navman

Sheet Multi Delivery&Install Details
A1: ALL PLATFORMS
A6: Multiple Delivery and Install Details
A8: Company Name | B8: Contact Name | C8: Contact Phone | D8: Contact Email | E8: Delivery Address | F8: Notes
A35: © 2022 Teletrac Navman

Sheet Fleet Information
F1: TN360
A6: Fleet Information
A9: Fleet Name* | B9: Cosmo Cranes
A11: Vehicle & Equipment Information
A12: Make* | B12: Model* | C12: Year* | D12: Registration* | E12: State* | F12: Vin* | G12: Serial Numbers (Renewals Only) | H12: Vehicle Name | I12: Engine Specification | J12: ATS Functionality Position only Movement
J13: ---Select---
J14: ---Select--- | L14: ---Select---
J15: ---Select--- | L15: Position only
J16: ---Select---
J17: ---Select---
J18: ---Select---
J19: ---Select---
J20: ---Select---
J21: ---Select---
J22: ---Select---
J23: ---Select---
J24: ---Select---
J25: ---Select---
J26: ---Select---
J27: ---Select---
... J46: ---Select---
J47: ---Select--- | L47: ---Select---
J48: ---Select--- | L48: Position only
J49: ---Select--- | L49: movement
J50: ---Select---
J51: ---Select---
J52: ---Select---
J53: ---Select---
J54: ---Select---
J55: ---Select---
J56: ---Select---
J57: ---Select---
J58: ---Select---
J59: ---Select---
J60: ---Select---
J61: ---Select---
... J106: ---Select---
J107: ---Select--- | L107: movement
J108: ---Select---
J109: ---Select---
...

Sheet Customer Login Details
D1: TN360
A6: Customer Login Details
A15: Name of User* | B15: Email Address of User* | C15: Other
A35: --Select--
A36: Yes
A37: No

Sheet Onboarding Fleet
D1: Please Enter the Order Details below | N1: TN360
D2: To ensure a fast order and provisioning process please complete all relevant information.
B5: TN360 Company Name* | C5: Cosmo Cranes | I5: Director Sync Enabled? | K5: TRUE
B7: BRANCHES & FLEETS | F7: IMPLEMENTATION MANAGERS
B8: - List any branches that your company has. This is where we link drivers/users to their homebase. - List your vehicle groups. This will help organise your vehicles. | F8: - Please list up to three Implementation Managers below, & enter Licence details if implementation manager is also a driver. (leave blank if not a driver) - All contacts listed below will receive a Welcome Pack including information on how to add further users and Drivers to the platform. | L8: - Hover your mouse over the column header for more information. - Please note for Health and Safety purposes, all contacts cannot opt out of System outage notices.
B10: Branch Name | C10: Address | D10: Fleet Name(s)* | F10: First Name* | G10: Last Name* | H10: Permissions | I10: Licence State | J10: Licence # | K10: Mobile Number | L10: Email* | M10: Time Zone* | N10: Branch* | O10: Ruleset*
B12: Camberwell | C12: 4/990 Toorak Rd Camberwell VIC 3124 | D12: AU | F12: Joe | G12: Bloggs | H12: Admin | I12: NSW | J12: 1234AA | K12: 61401234567 | L12: jane.doe@teletracnavman.com | M12: Australia/Melbourne | N12: Camberwell
B13: Auckland | C13: 67 Apollo Dr, Rosedale, Auckland, 0632 | D13: NZ Fleet | L13: jane.doe@teletracnavman.com
D14: Trailers
B35: * Denotes Required Fields
A41: Select
A42: Compliance Essential
A43: Compliance Professional
A44: IAP Essential/Professional
A45: Onboard Mass IAP
A46: Onboard Mass non IAP
A47: HPV/RIM
A48: iFace/MT201 Applications
A50: Select
A51: VIC
A52: NSW
A53: QLD
... A58: NT

Sheet Onboarding Vehicles
D1: Please Enter the Order Details below | W1: TN360
D2: To ensure a fast order and provisioning process please complete all relevant information.
B5: MT201 PRETRIP CHECKLISTS | E5: (Y or N) | H5: iFace (MT201) NEW UI | Q5: MT201 SPEED ALERT SETTINGS | V5: Speed Limit | W5: Threshold | X5: Time
C6: Would you like us to add the standard NHVAS Pretrip Checklist to the MT201 devices? | E6: N | H6: If the customer has ordered a new application (SmartNav, EWD etc) then the new UI is required. If these are on an existing iFace then these devices will need to be updated to the new UI. | R6: This setting dictates when a speed event registers. The standard configuration is 107 km/h for 5+ seconds before an alert is created. | V6: 100 km/h | W6: e | X6: 5 Seconds
B8: VEHICLES | N8: Additional Comments | S8: MT201 Options
B9: - List details of each vehicle. Vehicle Name can be the same as the Vehicle registration. - List all of the items required per vehicle, one per line. - Vehicles can be placed into multiple fleets. - If the fleet details are not added then it will be the customers responsibilty to do this at a later stage. | G9: - All cells that highlight once the product has been selected are Mandatory - Vehicle name will match registration, enter a new name if this is to be different from the default. - If the vehicle does not have a registration then enter a meaningful name. | S9: Obtain Pre-Trip information To be completed if applications are required by (*)
B11: Vehicle Total | D11: Solar Tracker Total | E11: ATS Total | G11: Please Delete the Red Text in the table below and replace with vehilce details from the sale | N11: VPM Total | O11: VPM Cables Total | P11: DVR Total
B12: =COUNTA(B15:B417) -> 2 | D12: =COUNTIF(C15:C417,"Solar Tracker") -> 1 | E12: =COUNTIF(C15:C417,"ATS*") -> 0 | N12: =COUNTIF(N15:N417,"Yes") -> 1 | O12: =COUNTIF(O15:O417,"<>"&A71) -> 0 | P12: =COUNTA(P15:P417) -> 0
B14: Registration | C14: Product/Bundle* | D14: Vehicle Name | E14: Reg. State | F14: Rego | G14: VIN | H14: Vehicle Type | I14: Make | J14: Model | K14: Fleet 1 | L14: Fleet 2 | N14: VPM? | O14: VPM Cable? | P14: DVR Camera Bundle | Q14: Notes | S14: Messaging | T14: Speed Assist | U14: SmartNav | V14: SmartNav Route | W14: Easy Docs | X14: Forms | Y14: EWD
A15: Select | B15: 1JG3JK | C15: Tracking Professional (VT101) | D15: =B15 -> 1JG3JK | E15: NSW | F15: =IF(B15="","",B15) -> 1JG3JK | G15: 65F45678643132 | H15: Default | I15: Kenworth | J15: K900 | K15: Trailers | N15: Yes | O15: No | Z15: =IF(Y15="Yes","Please ensure the UI has been upgraded","")
A16: #1 IAP Essential | B16: Bin 1 | C16: Solar Tracker | D16: =B16 -> Bin 1 | E16: NSW | F16: =IF(B16="","",B16) -> Bin 1 | H16: Default | N16: No | O16: No | Z16: =IF(Y16="Yes","Please ensure the UI has been upgraded","")
A17: #2 IAP Professional | C17: Select | D17: =B17 -> 0 | E17: Select | F17: =IF(B17="","",B17) | N17: No | O17: No | Z17: =IF(Y17="Yes","Please ensure the UI has been upgraded","")
A18: #3 IAP Essential | C18: Select | D18: =B18 -> 0 | E18: Select | F18: =IF(B18="","",B18) | N18: No | O18: No | Z18: =IF(Y18="Yes","Please ensure the UI has been upgraded","")
A19: #4 IAP Essential | C19: Select | D19: =B19 -> 0 | E19: Select | F19: =IF(B19="","",B19) | N19: No | O19: No | Z19: =IF(Y19="Yes","Please ensure the UI has been upgraded","")
A20: #5 IAP Professional | C20: Select | D20: =B20 -> 0 | E20: Select | F20: =IF(B20="","",B20) | N20: No | O20: No | Z20: =IF(Y20="Yes","Please ensure the UI has been upgraded","")
A21: #6 IAP Only | C21: Select | D21: =B21 -> 0 | E21: Select | F21: =IF(B21="","",B21) | N21: No | O21: No | Z21: =IF(Y21="Yes","Please ensure the UI has been upgraded","")
A22: ATS1 | C22: Select | D22: =B22 -> 0 | E22: Select | F22: =IF(B22="","",B22) | N22: No | O22: No | Z22: =IF(Y22="Yes","Please ensure the UI has been upgraded","")
A23: ATS2 | C23: Select | D23: =B23 -> 0 | E23: Select | F23: =IF(B23="","",B23) | N23: No | O23: No | Z23: =IF(Y23="Yes","Please ensure the UI has been upgraded","")
A24: Compliance Essential | C24: Select | D24: =B24 -> 0 | E24: Select | F24: =IF(B24="","",B24) | N24: No | O24: No | Z24: =IF(Y24="Yes","Please ensure the UI has been upgraded","")
A25: Compliance Professional | C25: Select | D25: =B25 -> 0 | E25: Select | F25: =IF(B25="","",B25) | N25: No | O25: No | Z25: =IF(Y25="Yes","Please ensure the UI has been upgraded","")
A26: iFace/MT201 Applications | C26: Select | D26: =B26 -> 0 | E26: Select | F26: =IF(B26="","",B26) | N26: No | O26: No | Z26: =IF(Y26="Yes","Please ensure the UI has been upgraded","")
A27: MT501 | C27: Select | D27: =B27 -> 0 | E27: Select | F27: =IF(B27="","",B27) | N27: No | O27: No | Z27: =IF(Y27="Yes","Please ensure the UI has been upgraded","")
A28: NSW | C28: Select | D28: =B28 -> 0 | E28: Select | F28: =IF(B28="","",B28) | N28: No | O28: No | Z28: =IF(Y28="Yes","Please ensure the UI has been upgraded","")
... A38: Tracking Professional (Vt102) | C38: Select | D38: =B38 -> 0 | E38: Select | F38: =IF(B38="","",B38) | N38: No | O38: No | Z38: =IF(Y38="Yes","Please ensure the UI has been upgraded","")
C39: Select | D39: =B39 -> 0 | E39: Select | F39: =IF(B39="","",B39) | N39: No | O39: No | Z39: =IF(Y39="Yes","Please ensure the UI has been upgraded","")
C40: Select | D40: =B40 -> 0 | E40: Select | F40: =IF(B40="","",B40) | N40: No | O40: No | Z40: =IF(Y40="Yes","Please ensure the UI has been upgraded","")
C41: Select | D41: =B41 -> 0 | E41: Select | F41: =IF(B41="","",B41) | N41: No | O41: No | Z41: =IF(Y41="Yes","Please ensure the UI has been upgraded","")
C42: Select | D42: =B42 -> 0 | E42: Select | F42: =IF(B42="","",B42) | N42: No | O42: No
C43: Select | D43: =B43 -> 0 | E43: Select | F43: =IF(B43="","",B43) | N43: No | O43: No
C44: Select | D44: =B44 -> 0 | E44: Select | F44: =IF(B44="","",B44) | N44: No | O44: No
C45: Select | D45: =B45 -> 0 | E45: Select | F45: =IF(B45="","",B45) | N45: No | O45: No
A46: Select | C46: Select | D46: =B46 -> 0 | E46: Select | F46: =IF(B46="","",B46) | N46: No | O46: No
A47: VIC | C47: Select | D47: =B47 -> 0 | E47: Select | F47: =IF(B47="","",B47) | N47: No | O47: No | Z47: =IF(Y47="Yes","Please ensure the UI has been upgraded","")
A48: NSW | C48: Select | D48: =B48 -> 0 | E48: Select | F48: =IF(B48="","",B48) | N48: No | O48: No | Z48: =IF(Y48="Yes","Please ensure the UI has been upgraded","")
A49: QLD | C49: Select | D49: =B49 -> 0 | E49: Select | F49: =IF(B49="","",B49) | N49: No | O49: No | Z49: =IF(Y49="Yes","Please ensure the UI has been upgraded","")
A50: SA | C50: Select | D50: =B50 -> 0 | E50: Select | F50: =IF(B50="","",B50) | N50: No | O50: No | Z50: =IF(Y50="Yes","Please ensure the UI has been upgraded","")
A51: ACT | C51: Select | D51: =B51 -> 0 | E51: Select | F51: =IF(B51="","",B51) | N51: No | O51: No | Z51: =IF(Y51="Yes","Please ensure the UI has been upgraded","")
A52: WA | C52: Select | D52: =B52 -> 0 | E52: Select | F52: =IF(B52="","",B52) | N52: No | O52: No | Z52: =IF(Y52="Yes","Please ensure the UI has been upgraded","")
A53: TAS | C53: Select | D53: =B53 -> 0 | E53: Select | F53: =IF(B53="","",B53) | N53: No | O53: No | Z53: =IF(Y53="Yes","Please ensure the UI has been upgraded","")
A54: NT | C54: Select | D54: =B54 -> 0 | E54: Select | F54: =IF(B54="","",B54) | N54: No | O54: No | Z54: =IF(Y54="Yes","Please ensure the UI has been upgraded","")
...

Sheet Renewal Transfer
F1: TN360
A4: Fleet Information
A7: Fleet Name* | B7: Cosmo Cranes | E7: Account Name* | F7: Cosmo Cranes Pty Ltd
A9: Vehicle & Equipment Information
A11: Make* | B11: Model* | C11: Year* | D11: Registration* | E11: State* | F11: Vin* | G11: Serial Number (Renewals/Transfers Only) | H11: Vehicle Name
A161: © 2021 Teletrac Navman
